/var/spool/slurm/job36382661/slurm_script: line 17: /ibex/user/alvarem/miniconda3/bin/activate: No such file or directory
multiprocessing.pool.RemoteTraceback: 
"""
Traceback (most recent call last):
  File "/home/alvarem/miniconda3/envs/loc/lib/python3.9/multiprocessing/pool.py", line 125, in worker
    result = (True, func(*args, **kwds))
  File "/home/alvarem/miniconda3/envs/loc/lib/python3.9/multiprocessing/pool.py", line 48, in mapstar
    return list(map(*args))
  File "/home/alvarem/bridge/Par_loc.py", line 521, in Prl_Grad_chain
    np.random.seed(seed)
  File "mtrand.pyx", line 4789, in numpy.random.mtrand.seed
  File "mtrand.pyx", line 250, in numpy.random.mtrand.RandomState.seed
  File "_mt19937.pyx", line 166, in numpy.random._mt19937.MT19937._legacy_seeding
  File "_mt19937.pyx", line 180, in numpy.random._mt19937.MT19937._legacy_seeding
ValueError: Seed must be between 0 and 2**32 - 1
"""

The above exception was the direct cause of the following exception:

Traceback (most recent call last):
  File "/home/alvarem/bridge/Par_loc.py", line 772, in <module>
    if __name__ == '__main__': 
  File "/home/alvarem/miniconda3/envs/loc/lib/python3.9/multiprocessing/pool.py", line 364, in map
    return self._map_async(func, iterable, mapstar, chunksize).get()
  File "/home/alvarem/miniconda3/envs/loc/lib/python3.9/multiprocessing/pool.py", line 771, in get
    raise self._value
ValueError: Seed must be between 0 and 2**32 - 1
