/var/spool/slurm/job36975741/slurm_script: line 19: /ibex/user/alvarem/miniconda3/bin/activate: No such file or directory
/home/alvarem/bridge/bridge.py:2755: RuntimeWarning: invalid value encountered in scalar divide
  P=(1-P_0)/np.sum((eLes[1:]+1)*np.log(eLes[1:]+1)**2/2**(beta*eLes[1:]))
multiprocessing.pool.RemoteTraceback: 
"""
Traceback (most recent call last):
  File "/home/alvarem/miniconda3/envs/loc/lib/python3.9/multiprocessing/pool.py", line 125, in worker
    result = (True, func(*args, **kwds))
  File "/home/alvarem/miniconda3/envs/loc/lib/python3.9/multiprocessing/pool.py", line 48, in mapstar
    return list(map(*args))
  File "/home/alvarem/bridge/Par_loc.py", line 1079, in Prl_Unbiased
    P0=(1+CP*eSes[1]**(beta)*np.sum((ePes[1:]+1)*np.log(ePes[1:]+1)**2/eSes[1:]**(beta))\
IndexError: index 1 is out of bounds for axis 0 with size 1
"""

The above exception was the direct cause of the following exception:

Traceback (most recent call last):
  File "/home/alvarem/bridge/Par_loc.py", line 1297, in <module>
    pool_outputs = pool.map(Prl_Unbiased,inputs)
  File "/home/alvarem/miniconda3/envs/loc/lib/python3.9/multiprocessing/pool.py", line 364, in map
    return self._map_async(func, iterable, mapstar, chunksize).get()
  File "/home/alvarem/miniconda3/envs/loc/lib/python3.9/multiprocessing/pool.py", line 771, in get
    raise self._value
IndexError: index 1 is out of bounds for axis 0 with size 1
