/var/spool/slurm/job35913700/slurm_script: line 17: /ibex/user/alvarem/miniconda3/bin/activate: No such file or directory
multiprocessing.pool.RemoteTraceback: 
"""
Traceback (most recent call last):
  File "/home/alvarem/miniconda3/envs/loc/lib/python3.9/multiprocessing/pool.py", line 125, in worker
    result = (True, func(*args, **kwds))
  File "/home/alvarem/miniconda3/envs/loc/lib/python3.9/multiprocessing/pool.py", line 48, in mapstar
    return list(map(*args))
  File "/home/alvarem/bridge/Par_loc.py", line 464, in Prl_C_SGD_ou_bridge
    bdg.C_Grad_Cond_PF_bridge_back_samp(cond_path_0,cond_path_1,seeds_cond_0,seeds_cond_1,t0,x0,T,b,\
  File "/home/alvarem/bridge/bridge.py", line 5248, in C_Grad_Cond_PF_bridge_back_samp
    =C_Cond_PF_bridge_back_samp(x_cond_0,x_cond_1,\
  File "/home/alvarem/bridge/bridge.py", line 4634, in C_Cond_PF_bridge_back_samp
    [part_resamp_0,part_resamp_1,x_new_0, x_new_1]=max_coup_multi(weights_0,weights_1,N,x_last_0,x_last_1,1)
  File "/home/alvarem/bridge/bridge.py", line 1980, in max_coup_multi
    [part0_prox,x0_new_prox]=multi_samp_exp(w4_den,N,x0,dim)
UnboundLocalError: local variable 'w4_den' referenced before assignment
"""

The above exception was the direct cause of the following exception:

Traceback (most recent call last):
  File "/home/alvarem/bridge/Par_loc.py", line 615, in <module>
    pool_outputs = pool.map(Prl_C_SGD_ou_bridge,inputs)
  File "/home/alvarem/miniconda3/envs/loc/lib/python3.9/multiprocessing/pool.py", line 364, in map
    return self._map_async(func, iterable, mapstar, chunksize).get()
  File "/home/alvarem/miniconda3/envs/loc/lib/python3.9/multiprocessing/pool.py", line 771, in get
    raise self._value
UnboundLocalError: local variable 'w4_den' referenced before assignment
