/var/spool/slurm/job36382780/slurm_script: line 17: /ibex/user/alvarem/miniconda3/bin/activate: No such file or directory
multiprocessing.pool.RemoteTraceback: 
"""
Traceback (most recent call last):
  File "/home/alvarem/miniconda3/envs/loc/lib/python3.9/multiprocessing/pool.py", line 125, in worker
    result = (True, func(*args, **kwds))
  File "/home/alvarem/miniconda3/envs/loc/lib/python3.9/multiprocessing/pool.py", line 48, in mapstar
    return list(map(*args))
  File "/home/alvarem/bridge/Par_loc.py", line 604, in Prl_C_Grad_chain
    ori_pf_l[k,i]=np.mean((x_pr),axis=1)
NameError: name 'k' is not defined
"""

The above exception was the direct cause of the following exception:

Traceback (most recent call last):
  File "/home/alvarem/bridge/Par_loc.py", line 849, in <module>
    pool_outputs = pool.map(Prl_C_Grad_chain,inputs)
  File "/home/alvarem/miniconda3/envs/loc/lib/python3.9/multiprocessing/pool.py", line 364, in map
    return self._map_async(func, iterable, mapstar, chunksize).get()
  File "/home/alvarem/miniconda3/envs/loc/lib/python3.9/multiprocessing/pool.py", line 771, in get
    raise self._value
NameError: name 'k' is not defined
